2025-03-18 09:21:21,616 INFO    MainThread:10176 [wandb_setup.py:_flush():67] Current SDK version is 0.19.8
2025-03-18 09:21:21,616 INFO    MainThread:10176 [wandb_setup.py:_flush():67] Configure stats pid to 10176
2025-03-18 09:21:21,616 INFO    MainThread:10176 [wandb_setup.py:_flush():67] Loading settings from C:\Users\aritr\.config\wandb\settings
2025-03-18 09:21:21,616 INFO    MainThread:10176 [wandb_setup.py:_flush():67] Loading settings from C:\Users\aritr\Downloads\DA5401\Assignment1\da6401_assignment1\wandb\settings
2025-03-18 09:21:21,616 INFO    MainThread:10176 [wandb_setup.py:_flush():67] Loading settings from environment variables
2025-03-18 09:21:21,617 INFO    MainThread:10176 [wandb_init.py:setup_run_log_directory():647] Logging user logs to C:\Users\aritr\Downloads\DA5401\Assignment1\da6401_assignment1\wandb\run-20250318_092121-e1wwa2n5\logs\debug.log
2025-03-18 09:21:21,617 INFO    MainThread:10176 [wandb_init.py:setup_run_log_directory():648] Logging internal logs to C:\Users\aritr\Downloads\DA5401\Assignment1\da6401_assignment1\wandb\run-20250318_092121-e1wwa2n5\logs\debug-internal.log
2025-03-18 09:21:21,617 INFO    MainThread:10176 [wandb_init.py:init():761] calling init triggers
2025-03-18 09:21:21,617 INFO    MainThread:10176 [wandb_init.py:init():766] wandb.init called with sweep_config: {}
config: {'_wandb': {}}
2025-03-18 09:21:21,617 INFO    MainThread:10176 [wandb_init.py:init():784] starting backend
2025-03-18 09:21:21,617 INFO    MainThread:10176 [wandb_init.py:init():788] sending inform_init request
2025-03-18 09:21:21,631 INFO    MainThread:10176 [backend.py:_multiprocessing_setup():101] multiprocessing start_methods=spawn, using: spawn
2025-03-18 09:21:21,631 INFO    MainThread:10176 [wandb_init.py:init():798] backend started and connected
2025-03-18 09:21:21,632 INFO    MainThread:10176 [wandb_init.py:init():891] updated telemetry
2025-03-18 09:21:21,682 INFO    MainThread:10176 [wandb_init.py:init():915] communicating run to backend with 90.0 second timeout
2025-03-18 09:21:22,219 ERROR   MainThread:10176 [wandb_init.py:init():1478] error in wandb.init()
Traceback (most recent call last):
  File "C:\Users\aritr\AppData\Local\Programs\Python\Python310\lib\site-packages\wandb\sdk\wandb_init.py", line 1468, in init
    return wi.init(run_settings, run_config)
  File "C:\Users\aritr\AppData\Local\Programs\Python\Python310\lib\site-packages\wandb\sdk\wandb_init.py", line 963, in init
    raise error
wandb.errors.errors.CommError: failed to upsert bucket: returned error 404: {"data":{"upsertBucket":null},"errors":[{"message":"entity da24m004-iitmanaa-org not found during upsertBucket","path":["upsertBucket"]}]}
2025-03-18 09:21:23,230 INFO    MsgRouterThr:10176 [mailbox.py:close():129] Closing mailbox, abandoning 0 handles.
